[2024-02-20T21:10:43.241+0000] {taskinstance.py:1956} INFO - Dependencies all met for dep_context=non-requeueable deps ti=<TaskInstance: triggerdag2.tsk1 manual__2024-02-20T21:10:41.610427+00:00 [queued]>
[2024-02-20T21:10:43.251+0000] {taskinstance.py:1956} INFO - Dependencies all met for dep_context=requeueable deps ti=<TaskInstance: triggerdag2.tsk1 manual__2024-02-20T21:10:41.610427+00:00 [queued]>
[2024-02-20T21:10:43.252+0000] {taskinstance.py:2170} INFO - Starting attempt 1 of 1
[2024-02-20T21:10:43.270+0000] {taskinstance.py:2191} INFO - Executing <Task(BashOperator): tsk1> on 2024-02-20 21:10:41.610427+00:00
[2024-02-20T21:10:43.281+0000] {standard_task_runner.py:60} INFO - Started process 947 to run task
[2024-02-20T21:10:43.284+0000] {standard_task_runner.py:87} INFO - Running: ['***', 'tasks', 'run', 'triggerdag2', 'tsk1', 'manual__2024-02-20T21:10:41.610427+00:00', '--job-id', '29', '--raw', '--subdir', 'DAGS_FOLDER/triggerDag2.py', '--cfg-path', '/tmp/tmphp1yfpfk']
[2024-02-20T21:10:43.286+0000] {standard_task_runner.py:88} INFO - Job 29: Subtask tsk1
[2024-02-20T21:10:43.340+0000] {task_command.py:423} INFO - Running <TaskInstance: triggerdag2.tsk1 manual__2024-02-20T21:10:41.610427+00:00 [running]> on host a98526a907f7
[2024-02-20T21:10:43.443+0000] {taskinstance.py:2480} INFO - Exporting env vars: AIRFLOW_CTX_DAG_OWNER='***' AIRFLOW_CTX_DAG_ID='triggerdag2' AIRFLOW_CTX_TASK_ID='tsk1' AIRFLOW_CTX_EXECUTION_DATE='2024-02-20T21:10:41.610427+00:00' AIRFLOW_CTX_TRY_NUMBER='1' AIRFLOW_CTX_DAG_RUN_ID='manual__2024-02-20T21:10:41.610427+00:00'
[2024-02-20T21:10:43.445+0000] {subprocess.py:63} INFO - Tmp dir root location: /tmp
[2024-02-20T21:10:43.446+0000] {subprocess.py:75} INFO - Running command: ['/usr/bin/bash', '-c', 'exit 1']
[2024-02-20T21:10:43.474+0000] {subprocess.py:86} INFO - Output:
[2024-02-20T21:10:43.477+0000] {subprocess.py:97} INFO - Command exited with return code 1
[2024-02-20T21:10:43.491+0000] {taskinstance.py:2698} ERROR - Task failed with exception
Traceback (most recent call last):
  File "/home/airflow/.local/lib/python3.8/site-packages/airflow/models/taskinstance.py", line 433, in _execute_task
    result = execute_callable(context=context, **execute_callable_kwargs)
  File "/home/airflow/.local/lib/python3.8/site-packages/airflow/operators/bash.py", line 212, in execute
    raise AirflowException(
airflow.exceptions.AirflowException: Bash command failed. The command returned a non-zero exit code 1.
[2024-02-20T21:10:43.496+0000] {taskinstance.py:1138} INFO - Marking task as FAILED. dag_id=triggerdag2, task_id=tsk1, execution_date=20240220T211041, start_date=20240220T211043, end_date=20240220T211043
[2024-02-20T21:10:43.517+0000] {standard_task_runner.py:107} ERROR - Failed to execute job 29 for task tsk1 (Bash command failed. The command returned a non-zero exit code 1.; 947)
[2024-02-20T21:10:43.537+0000] {local_task_job_runner.py:234} INFO - Task exited with return code 1
[2024-02-20T21:10:43.569+0000] {taskinstance.py:3280} INFO - 1 downstream tasks scheduled from follow-on schedule check
