[2024-02-20T21:19:33.816+0000] {taskinstance.py:1956} INFO - Dependencies all met for dep_context=non-requeueable deps ti=<TaskInstance: triggerdag3.tsk1 manual__2024-02-20T21:19:32.883537+00:00 [queued]>
[2024-02-20T21:19:33.827+0000] {taskinstance.py:1956} INFO - Dependencies all met for dep_context=requeueable deps ti=<TaskInstance: triggerdag3.tsk1 manual__2024-02-20T21:19:32.883537+00:00 [queued]>
[2024-02-20T21:19:33.827+0000] {taskinstance.py:2170} INFO - Starting attempt 1 of 1
[2024-02-20T21:19:33.838+0000] {taskinstance.py:2191} INFO - Executing <Task(BashOperator): tsk1> on 2024-02-20 21:19:32.883537+00:00
[2024-02-20T21:19:33.847+0000] {standard_task_runner.py:60} INFO - Started process 1329 to run task
[2024-02-20T21:19:33.850+0000] {standard_task_runner.py:87} INFO - Running: ['***', 'tasks', 'run', 'triggerdag3', 'tsk1', 'manual__2024-02-20T21:19:32.883537+00:00', '--job-id', '39', '--raw', '--subdir', 'DAGS_FOLDER/triggerDag3.py', '--cfg-path', '/tmp/tmpjtxpehm1']
[2024-02-20T21:19:33.851+0000] {standard_task_runner.py:88} INFO - Job 39: Subtask tsk1
[2024-02-20T21:19:33.925+0000] {task_command.py:423} INFO - Running <TaskInstance: triggerdag3.tsk1 manual__2024-02-20T21:19:32.883537+00:00 [running]> on host a98526a907f7
[2024-02-20T21:19:34.015+0000] {taskinstance.py:2480} INFO - Exporting env vars: AIRFLOW_CTX_DAG_OWNER='***' AIRFLOW_CTX_DAG_ID='triggerdag3' AIRFLOW_CTX_TASK_ID='tsk1' AIRFLOW_CTX_EXECUTION_DATE='2024-02-20T21:19:32.883537+00:00' AIRFLOW_CTX_TRY_NUMBER='1' AIRFLOW_CTX_DAG_RUN_ID='manual__2024-02-20T21:19:32.883537+00:00'
[2024-02-20T21:19:34.016+0000] {subprocess.py:63} INFO - Tmp dir root location: /tmp
[2024-02-20T21:19:34.017+0000] {subprocess.py:75} INFO - Running command: ['/usr/bin/bash', '-c', 'exit 1']
[2024-02-20T21:19:34.035+0000] {subprocess.py:86} INFO - Output:
[2024-02-20T21:19:34.038+0000] {subprocess.py:97} INFO - Command exited with return code 1
[2024-02-20T21:19:34.049+0000] {taskinstance.py:2698} ERROR - Task failed with exception
Traceback (most recent call last):
  File "/home/airflow/.local/lib/python3.8/site-packages/airflow/models/taskinstance.py", line 433, in _execute_task
    result = execute_callable(context=context, **execute_callable_kwargs)
  File "/home/airflow/.local/lib/python3.8/site-packages/airflow/operators/bash.py", line 212, in execute
    raise AirflowException(
airflow.exceptions.AirflowException: Bash command failed. The command returned a non-zero exit code 1.
[2024-02-20T21:19:34.051+0000] {taskinstance.py:1138} INFO - Marking task as FAILED. dag_id=triggerdag3, task_id=tsk1, execution_date=20240220T211932, start_date=20240220T211933, end_date=20240220T211934
[2024-02-20T21:19:34.064+0000] {standard_task_runner.py:107} ERROR - Failed to execute job 39 for task tsk1 (Bash command failed. The command returned a non-zero exit code 1.; 1329)
[2024-02-20T21:19:34.105+0000] {local_task_job_runner.py:234} INFO - Task exited with return code 1
[2024-02-20T21:19:34.129+0000] {taskinstance.py:3280} INFO - 0 downstream tasks scheduled from follow-on schedule check
